Workbook

Sheet Reference
A1: Item | B1: Unit | C1: Calories / unit | D1: Protein / unit | E1: Fat / unit | F1: Carbs / unit | G1: Fiber / unit
A2: Whole eggs | B2: # | C2: 72 | D2: 6.3 | E2: 4.8 | F2: 0.4 | G2: 0
A3: Egg whites | B3: gram | C3: 0.52 | D3: 0.11 | E3: 0 | F3: 0.01 | G3: 0
A4: Jocko protein powder | B4: gram | C4: 3.53 | D4: 0.65 | E4: 0.07 | F4: 0.15 | G4: 0
A5: Dry oats | B5: gram | C5: 3.9 | D5: 0.17 | E5: 0.07 | F5: 0.66 | G5: 0.1
A6: Whole milk (3.25% fat) | B6: gram | C6: 0.61 | D6: 0.03 | E6: 0.03 | F6: 0.05 | G6: 0
A7: Chicken breast (Raw) | B7: gram | C7: 1.2 | D7: 0.23 | E7: 0.03 | F7: 0 | G7: 0
A8: Jasmine rice (Uncooked) | B8: gram | C8: 3.6 | D8: 0.08 | E8: 0.01 | F8: 0.8 | G8: 0.01
A9: Broccoli | B9: gram | C9: 0.34 | D9: 0.03 | E9: 0 | F9: 0.07 | G9: 0.03
A10: Non-fat Greek yogurt | B10: gram | C10: 0.59 | D10: 0.1 | E10: 0 | F10: 0.04 | G10: 0
A11: Blueberries | B11: gram | C11: 0.57 | D11: 0.01 | E11: 0 | F11: 0.15 | G11: 0.02
A12: Almonds | B12: gram | C12: 5.8 | D12: 0.21 | E12: 0.5 | F12: 0.22 | G12: 0.13
A13: 93% lean ground beef (Raw) | B13: gram | C13: 1.72 | D13: 0.25 | E13: 0.08 | F13: 0 | G13: 0
... A39: Spinach (Raw) | B39: gram | C39: 0.23 | D39: 0.029 | E39: 0.004 | F39: 0.036 | G39: 0.022
A40: Note: Change/Add if necessary.

Sheet Reference Meal Plan
A1: Daily Meal Plan Sample
A2: Item | B2: Amount | C2: Unit | D2: Calories | E2: Protein (g) | F2: Fat (g) | G2: Carbs (g) | H2: Fiber (g)
A3: BREAKFAST
A4: Option A
A5: Frozen mixed berries | B5: 120 | C5: =INDEX(Reference!$B$2:$B$39,MATCH($A5,Reference!$A$2:$A$39,0)) -> gram | D5: =$B5*INDEX(Reference!$C$2:$C$39,MATCH($A5,Reference!$A$2:$A$39,0)) -> 66 | E5: =$B5*INDEX(Reference!$D$2:$D$39,MATCH($A5,Reference!$A$2:$A$39,0)) -> 1.2 | F5: =$B5*INDEX(Reference!$E$2:$E$39,MATCH($A5,Reference!$A$2:$A$39,0)) -> 0 | G5: =$B5*INDEX(Reference!$F$2:$F$39,MATCH($A5,Reference!$A$2:$A$39,0)) -> 15.6 | H5: =$B5*INDEX(Reference!$G$2:$G$39,MATCH($A5,Reference!$A$2:$A$39,0)) -> 2.4
A6: Banana | B6: 120 | C6: =INDEX(Reference!$B$2:$B$39,MATCH($A6,Reference!$A$2:$A$39,0)) -> gram | D6: =$B6*INDEX(Reference!$C$2:$C$39,MATCH($A6,Reference!$A$2:$A$39,0)) -> 106.8 | E6: =$B6*INDEX(Reference!$D$2:$D$39,MATCH($A6,Reference!$A$2:$A$39,0)) -> 1.2 | F6: =$B6*INDEX(Reference!$E$2:$E$39,MATCH($A6,Reference!$A$2:$A$39,0)) -> 0 | G6: =$B6*INDEX(Reference!$F$2:$F$39,MATCH($A6,Reference!$A$2:$A$39,0)) -> 27.6 | H6: =$B6*INDEX(Reference!$G$2:$G$39,MATCH($A6,Reference!$A$2:$A$39,0)) -> 3.6
A7: Whole milk (3.25% fat) | B7: 400 | C7: =INDEX(Reference!$B$2:$B$39,MATCH($A7,Reference!$A$2:$A$39,0)) -> gram | D7: =$B7*INDEX(Reference!$C$2:$C$39,MATCH($A7,Reference!$A$2:$A$39,0)) -> 244 | E7: =$B7*INDEX(Reference!$D$2:$D$39,MATCH($A7,Reference!$A$2:$A$39,0)) -> 12 | F7: =$B7*INDEX(Reference!$E$2:$E$39,MATCH($A7,Reference!$A$2:$A$39,0)) -> 12 | G7: =$B7*INDEX(Reference!$F$2:$F$39,MATCH($A7,Reference!$A$2:$A$39,0)) -> 20 | H7: =$B7*INDEX(Reference!$G$2:$G$39,MATCH($A7,Reference!$A$2:$A$39,0)) -> 0
A8: Jocko protein powder | B8: 45 | C8: =INDEX(Reference!$B$2:$B$39,MATCH($A8,Reference!$A$2:$A$39,0)) -> gram | D8: =$B8*INDEX(Reference!$C$2:$C$39,MATCH($A8,Reference!$A$2:$A$39,0)) -> 158.85 | E8: =$B8*INDEX(Reference!$D$2:$D$39,MATCH($A8,Reference!$A$2:$A$39,0)) -> 29.25 | F8: =$B8*INDEX(Reference!$E$2:$E$39,MATCH($A8,Reference!$A$2:$A$39,0)) -> 3.15 | G8: =$B8*INDEX(Reference!$F$2:$F$39,MATCH($A8,Reference!$A$2:$A$39,0)) -> 6.75 | H8: =$B8*INDEX(Reference!$G$2:$G$39,MATCH($A8,Reference!$A$2:$A$39,0)) -> 0
A9: Spinach (Raw) | B9: 30 | C9: =INDEX(Reference!$B$2:$B$39,MATCH($A9,Reference!$A$2:$A$39,0)) -> gram | D9: =$B9*INDEX(Reference!$C$2:$C$39,MATCH($A9,Reference!$A$2:$A$39,0)) -> 6.9 | E9: =$B9*INDEX(Reference!$D$2:$D$39,MATCH($A9,Reference!$A$2:$A$39,0)) -> 0.87 | F9: =$B9*INDEX(Reference!$E$2:$E$39,MATCH($A9,Reference!$A$2:$A$39,0)) -> 0.12 | G9: =$B9*INDEX(Reference!$F$2:$F$39,MATCH($A9,Reference!$A$2:$A$39,0)) -> 1.08 | H9: =$B9*INDEX(Reference!$G$2:$G$39,MATCH($A9,Reference!$A$2:$A$39,0)) -> 0.66
A10: Option A - Smoothie subtotal | D10: =SUM(D5:D9) -> 582.55 | E10: =SUM(E5:E9) -> 44.52 | F10: =SUM(F5:F9) -> 15.27 | G10: =SUM(G5:G9) -> 71.03 | H10: =SUM(H5:H9) -> 6.66
A11: Option B
A12: Dry oats | B12: 80 | C12: =INDEX(Reference!$B$2:$B$39,MATCH($A12,Reference!$A$2:$A$39,0)) -> gram | D12: =$B12*INDEX(Reference!$C$2:$C$39,MATCH($A12,Reference!$A$2:$A$39,0)) -> 312 | E12: =$B12*INDEX(Reference!$D$2:$D$39,MATCH($A12,Reference!$A$2:$A$39,0)) -> 13.6 | F12: =$B12*INDEX(Reference!$E$2:$E$39,MATCH($A12,Reference!$A$2:$A$39,0)) -> 5.6 | G12: =$B12*INDEX(Reference!$F$2:$F$39,MATCH($A12,Reference!$A$2:$A$39,0)) -> 52.8 | H12: =$B12*INDEX(Reference!$G$2:$G$39,MATCH($A12,Reference!$A$2:$A$39,0)) -> 8
A13: Whole milk (3.25% fat) | B13: 150 | C13: =INDEX(Reference!$B$2:$B$39,MATCH($A13,Reference!$A$2:$A$39,0)) -> gram | D13: =$B13*INDEX(Reference!$C$2:$C$39,MATCH($A13,Reference!$A$2:$A$39,0)) -> 91.5 | E13: =$B13*INDEX(Reference!$D$2:$D$39,MATCH($A13,Reference!$A$2:$A$39,0)) -> 4.5 | F13: =$B13*INDEX(Reference!$E$2:$E$39,MATCH($A13,Reference!$A$2:$A$39,0)) -> 4.5 | G13: =$B13*INDEX(Reference!$F$2:$F$39,MATCH($A13,Reference!$A$2:$A$39,0)) -> 7.5 | H13: =$B13*INDEX(Reference!$G$2:$G$39,MATCH($A13,Reference!$A$2:$A$39,0)) -> 0
A14: Non-fat Greek yogurt | B14: 150 | C14: =INDEX(Reference!$B$2:$B$39,MATCH($A14,Reference!$A$2:$A$39,0)) -> gram | D14: =$B14*INDEX(Reference!$C$2:$C$39,MATCH($A14,Reference!$A$2:$A$39,0)) -> 88.5 | E14: =$B14*INDEX(Reference!$D$2:$D$39,MATCH($A14,Reference!$A$2:$A$39,0)) -> 15 | F14: =$B14*INDEX(Reference!$E$2:$E$39,MATCH($A14,Reference!$A$2:$A$39,0)) -> 0 | G14: =$B14*INDEX(Reference!$F$2:$F$39,MATCH($A14,Reference!$A$2:$A$39,0)) -> 6 | H14: =$B14*INDEX(Reference!$G$2:$G$39,MATCH($A14,Reference!$A$2:$A$39,0)) -> 0
A15: Banana | B15: 80 | C15: =INDEX(Reference!$B$2:$B$39,MATCH($A15,Reference!$A$2:$A$39,0)) -> gram | D15: =$B15*INDEX(Reference!$C$2:$C$39,MATCH($A15,Reference!$A$2:$A$39,0)) -> 71.2 | E15: =$B15*INDEX(Reference!$D$2:$D$39,MATCH($A15,Reference!$A$2:$A$39,0)) -> 0.8 | F15: =$B15*INDEX(Reference!$E$2:$E$39,MATCH($A15,Reference!$A$2:$A$39,0)) -> 0 | G15: =$B15*INDEX(Reference!$F$2:$F$39,MATCH($A15,Reference!$A$2:$A$39,0)) -> 18.4 | H15: =$B15*INDEX(Reference!$G$2:$G$39,MATCH($A15,Reference!$A$2:$A$39,0)) -> 2.4
A16: Blueberries | B16: 40 | C16: =INDEX(Reference!$B$2:$B$39,MATCH($A16,Reference!$A$2:$A$39,0)) -> gram | D16: =$B16*INDEX(Reference!$C$2:$C$39,MATCH($A16,Reference!$A$2:$A$39,0)) -> 22.8 | E16: =$B16*INDEX(Reference!$D$2:$D$39,MATCH($A16,Reference!$A$2:$A$39,0)) -> 0.4 | F16: =$B16*INDEX(Reference!$E$2:$E$39,MATCH($A16,Reference!$A$2:$A$39,0)) -> 0 | G16: =$B16*INDEX(Reference!$F$2:$F$39,MATCH($A16,Reference!$A$2:$A$39,0)) -> 6 | H16: =$B16*INDEX(Reference!$G$2:$G$39,MATCH($A16,Reference!$A$2:$A$39,0)) -> 0.8
A17: Jocko protein powder | B17: 15 | C17: =INDEX(Reference!$B$2:$B$39,MATCH($A17,Reference!$A$2:$A$39,0)) -> gram | D17: =$B17*INDEX(Reference!$C$2:$C$39,MATCH($A17,Reference!$A$2:$A$39,0)) -> 52.95 | E17: =$B17*INDEX(Reference!$D$2:$D$39,MATCH($A17,Reference!$A$2:$A$39,0)) -> 9.75 | F17: =$B17*INDEX(Reference!$E$2:$E$39,MATCH($A17,Reference!$A$2:$A$39,0)) -> 1.05 | G17: =$B17*INDEX(Reference!$F$2:$F$39,MATCH($A17,Reference!$A$2:$A$39,0)) -> 2.25 | H17: =$B17*INDEX(Reference!$G$2:$G$39,MATCH($A17,Reference!$A$2:$A$39,0)) -> 0
A18: Option B - Overnight Oats subtotal | D18: =SUM(D12:D17) -> 638.95 | E18: =SUM(E12:E17) -> 44.05 | F18: =SUM(F12:F17) -> 11.15 | G18: =SUM(G12:G17) -> 92.95 | H18: =SUM(H12:H17) -> 11.2
A19: Option C
A20: Whole eggs | B20: 4 | C20: =INDEX(Reference!$B$2:$B$39,MATCH($A20,Reference!$A$2:$A$39,0)) -> # | D20: =$B20*INDEX(Reference!$C$2:$C$39,MATCH($A20,Reference!$A$2:$A$39,0)) -> 288 | E20: =$B20*INDEX(Reference!$D$2:$D$39,MATCH($A20,Reference!$A$2:$A$39,0)) -> 25.2 | F20: =$B20*INDEX(Reference!$E$2:$E$39,MATCH($A20,Reference!$A$2:$A$39,0)) -> 19.2 | G20: =$B20*INDEX(Reference!$F$2:$F$39,MATCH($A20,Reference!$A$2:$A$39,0)) -> 1.6 | H20: =$B20*INDEX(Reference!$G$2:$G$39,MATCH($A20,Reference!$A$2:$A$39,0)) -> 0
A21: Whole wheat bread | B21: 40 | C21: =INDEX(Reference!$B$2:$B$39,MATCH($A21,Reference!$A$2:$A$39,0)) -> gram | D21: =$B21*INDEX(Reference!$C$2:$C$39,MATCH($A21,Reference!$A$2:$A$39,0)) -> 100 | E21: =$B21*INDEX(Reference!$D$2:$D$39,MATCH($A21,Reference!$A$2:$A$39,0)) -> 5.2 | F21: =$B21*INDEX(Reference!$E$2:$E$39,MATCH($A21,Reference!$A$2:$A$39,0)) -> 1.6 | G21: =$B21*INDEX(Reference!$F$2:$F$39,MATCH($A21,Reference!$A$2:$A$39,0)) -> 16.4 | H21: =$B21*INDEX(Reference!$G$2:$G$39,MATCH($A21,Reference!$A$2:$A$39,0)) -> 2.8
A22: Avocado | B22: 120 | C22: =INDEX(Reference!$B$2:$B$39,MATCH($A22,Reference!$A$2:$A$39,0)) -> gram | D22: =$B22*INDEX(Reference!$C$2:$C$39,MATCH($A22,Reference!$A$2:$A$39,0)) -> 192 | E22: =$B22*INDEX(Reference!$D$2:$D$39,MATCH($A22,Reference!$A$2:$A$39,0)) -> 2.4 | F22: =$B22*INDEX(Reference!$E$2:$E$39,MATCH($A22,Reference!$A$2:$A$39,0)) -> 18 | G22: =$B22*INDEX(Reference!$F$2:$F$39,MATCH($A22,Reference!$A$2:$A$39,0)) -> 10.8 | H22: =$B22*INDEX(Reference!$G$2:$G$39,MATCH($A22,Reference!$A$2:$A$39,0)) -> 8.4
A23: Option C - Eggs & Toast subtotal | D23: =SUM(D20:D22) -> 580 | E23: =SUM(E20:E22) -> 32.8 | F23: =SUM(F20:F22) -> 38.8 | G23: =SUM(G20:G22) -> 28.8 | H23: =SUM(H20:H22) -> 11.2
A25: LUNCH
A26: Option A
A27: Chicken breast (Raw) | B27: 260 | C27: =INDEX(Reference!$B$2:$B$39,MATCH($A27,Reference!$A$2:$A$39,0)) -> gram | D27: =$B27*INDEX(Reference!$C$2:$C$39,MATCH($A27,Reference!$A$2:$A$39,0)) -> 312 | E27: =$B27*INDEX(Reference!$D$2:$D$39,MATCH($A27,Reference!$A$2:$A$39,0)) -> 59.8 | F27: =$B27*INDEX(Reference!$E$2:$E$39,MATCH($A27,Reference!$A$2:$A$39,0)) -> 7.8 | G27: =$B27*INDEX(Reference!$F$2:$F$39,MATCH($A27,Reference!$A$2:$A$39,0)) -> 0 | H27: =$B27*INDEX(Reference!$G$2:$G$39,MATCH($A27,Reference!$A$2:$A$39,0)) -> 0
A28: Raw sweet potato | B28: 220 | C28: =INDEX(Reference!$B$2:$B$39,MATCH($A28,Reference!$A$2:$A$39,0)) -> gram | D28: =$B28*INDEX(Reference!$C$2:$C$39,MATCH($A28,Reference!$A$2:$A$39,0)) -> 189.2 | E28: =$B28*INDEX(Reference!$D$2:$D$39,MATCH($A28,Reference!$A$2:$A$39,0)) -> 4.4 | F28: =$B28*INDEX(Reference!$E$2:$E$39,MATCH($A28,Reference!$A$2:$A$39,0)) -> 0 | G28: =$B28*INDEX(Reference!$F$2:$F$39,MATCH($A28,Reference!$A$2:$A$39,0)) -> 44 | H28: =$B28*INDEX(Reference!$G$2:$G$39,MATCH($A28,Reference!$A$2:$A$39,0)) -> 6.6
A29: Mixed salad (Lettuce, Tomato, Cucumber, Lemon) | B29: 1 | C29: =INDEX(Reference!$B$2:$B$39,MATCH($A29,Reference!$A$2:$A$39,0)) -> serving | D29: =$B29*INDEX(Reference!$C$2:$C$39,MATCH($A29,Reference!$A$2:$A$39,0)) -> 40 | E29: =$B29*INDEX(Reference!$D$2:$D$39,MATCH($A29,Reference!$A$2:$A$39,0)) -> 2 | F29: =$B29*INDEX(Reference!$E$2:$E$39,MATCH($A29,Reference!$A$2:$A$39,0)) -> 0.5 | G29: =$B29*INDEX(Reference!$F$2:$F$39,MATCH($A29,Reference!$A$2:$A$39,0)) -> 9 | H29: =$B29*INDEX(Reference!$G$2:$G$39,MATCH($A29,Reference!$A$2:$A$39,0)) -> 2
A30: Avocado | B30: 40 | C30: =INDEX(Reference!$B$2:$B$39,MATCH($A30,Reference!$A$2:$A$39,0)) -> gram | D30: =$B30*INDEX(Reference!$C$2:$C$39,MATCH($A30,Reference!$A$2:$A$39,0)) -> 64 | E30: =$B30*INDEX(Reference!$D$2:$D$39,MATCH($A30,Reference!$A$2:$A$39,0)) -> 0.8 | F30: =$B30*INDEX(Reference!$E$2:$E$39,MATCH($A30,Reference!$A$2:$A$39,0)) -> 6 | G30: =$B30*INDEX(Reference!$F$2:$F$39,MATCH($A30,Reference!$A$2:$A$39,0)) -> 3.6 | H30: =$B30*INDEX(Reference!$G$2:$G$39,MATCH($A30,Reference!$A$2:$A$39,0)) -> 2.8
A31: Olive oil | B31: 8 | C31: =INDEX(Reference!$B$2:$B$39,MATCH($A31,Reference!$A$2:$A$39,0)) -> gram | D31: =$B31*INDEX(Reference!$C$2:$C$39,MATCH($A31,Reference!$A$2:$A$39,0)) -> 70.72 | E31: =$B31*INDEX(Reference!$D$2:$D$39,MATCH($A31,Reference!$A$2:$A$39,0)) -> 0 | F31: =$B31*INDEX(Reference!$E$2:$E$39,MATCH($A31,Reference!$A$2:$A$39,0)) -> 8 | G31: =$B31*INDEX(Reference!$F$2:$F$39,MATCH($A31,Reference!$A$2:$A$39,0)) -> 0 | H31: =$B31*INDEX(Reference!$G$2:$G$39,MATCH($A31,Reference!$A$2:$A$39,0)) -> 0
A32: Option A subtotal | D32: =SUM(D27:D31) -> 675.92 | E32: =SUM(E27:E31) -> 67 | F32: =SUM(F27:F31) -> 22.3 | G32: =SUM(G27:G31) -> 56.6 | H32: =SUM(H27:H31) -> 11.4
A33: Option B
A34: Shrimp (Raw) | B34: 320 | C34: =INDEX(Reference!$B$2:$B$39,MATCH($A34,Reference!$A$2:$A$39,0)) -> gram | D34: =$B34*INDEX(Reference!$C$2:$C$39,MATCH($A34,Reference!$A$2:$A$39,0)) -> 316.8 | E34: =$B34*INDEX(Reference!$D$2:$D$39,MATCH($A34,Reference!$A$2:$A$39,0)) -> 76.8 | F34: =$B34*INDEX(Reference!$E$2:$E$39,MATCH($A34,Reference!$A$2:$A$39,0)) -> 0.96 | G34: =$B34*INDEX(Reference!$F$2:$F$39,MATCH($A34,Reference!$A$2:$A$39,0)) -> 0 | H34: =$B34*INDEX(Reference!$G$2:$G$39,MATCH($A34,Reference!$A$2:$A$39,0)) -> 0
A35: Jasmine rice (Uncooked) | B35: 70 | C35: =INDEX(Reference!$B$2:$B$39,MATCH($A35,Reference!$A$2:$A$39,0)) -> gram | D35: =$B35*INDEX(Reference!$C$2:$C$39,MATCH($A35,Reference!$A$2:$A$39,0)) -> 252 | E35: =$B35*INDEX(Reference!$D$2:$D$39,MATCH($A35,Reference!$A$2:$A$39,0)) -> 5.6 | F35: =$B35*INDEX(Reference!$E$2:$E$39,MATCH($A35,Reference!$A$2:$A$39,0)) -> 0.7 | G35: =$B35*INDEX(Reference!$F$2:$F$39,MATCH($A35,Reference!$A$2:$A$39,0)) -> 56 | H35: =$B35*INDEX(Reference!$G$2:$G$39,MATCH($A35,Reference!$A$2:$A$39,0)) -> 0.7
A36: Mixed salad (Lettuce, Tomato, Cucumber, Lemon) | B36: 1 | C36: =INDEX(Reference!$B$2:$B$39,MATCH($A36,Reference!$A$2:$A$39,0)) -> serving | D36: =$B36*INDEX(Reference!$C$2:$C$39,MATCH($A36,Reference!$A$2:$A$39,0)) -> 40 | E36: =$B36*INDEX(Reference!$D$2:$D$39,MATCH($A36,Reference!$A$2:$A$39,0)) -> 2 | F36: =$B36*INDEX(Reference!$E$2:$E$39,MATCH($A36,Reference!$A$2:$A$39,0)) -> 0.5 | G36: =$B36*INDEX(Reference!$F$2:$F$39,MATCH($A36,Reference!$A$2:$A$39,0)) -> 9 | H36: =$B36*INDEX(Reference!$G$2:$G$39,MATCH($A36,Reference!$A$2:$A$39,0)) -> 2
A37: Avocado | B37: 35 | C37: =INDEX(Reference!$B$2:$B$39,MATCH($A37,Reference!$A$2:$A$39,0)) -> gram | D37: =$B37*INDEX(Reference!$C$2:$C$39,MATCH($A37,Reference!$A$2:$A$39,0)) -> 56 | E37: =$B37*INDEX(Reference!$D$2:$D$39,MATCH($A37,Reference!$A$2:$A$39,0)) -> 0.7 | F37: =$B37*INDEX(Reference!$E$2:$E$39,MATCH($A37,Reference!$A$2:$A$39,0)) -> 5.25 | G37: =$B37*INDEX(Reference!$F$2:$F$39,MATCH($A37,Reference!$A$2:$A$39,0)) -> 3.15 | H37: =$B37*INDEX(Reference!$G$2:$G$39,MATCH($A37,Reference!$A$2:$A$39,0)) -> 2.45
A38: Non-fat Greek yogurt | B38: 35 | C38: =INDEX(Reference!$B$2:$B$39,MATCH($A38,Reference!$A$2:$A$39,0)) -> gram | D38: =$B38*INDEX(Reference!$C$2:$C$39,MATCH($A38,Reference!$A$2:$A$39,0)) -> 20.65 | E38: =$B38*INDEX(Reference!$D$2:$D$39,MATCH($A38,Reference!$A$2:$A$39,0)) -> 3.5 | F38: =$B38*INDEX(Reference!$E$2:$E$39,MATCH($A38,Reference!$A$2:$A$39,0)) -> 0 | G38: =$B38*INDEX(Reference!$F$2:$F$39,MATCH($A38,Reference!$A$2:$A$39,0)) -> 1.4 | H38: =$B38*INDEX(Reference!$G$2:$G$39,MATCH($A38,Reference!$A$2:$A$39,0)) -> 0
A39: Option B subtotal | D39: =SUM(D34:D38) -> 685.45 | E39: =SUM(E34:E38) -> 88.6 | F39: =SUM(F34:F38) -> 7.41 | G39: =SUM(G34:G38) -> 69.55 | H39: =SUM(H34:H38) -> 5.15
A40: Option C
A41: 93% lean ground beef (Raw) | B41: 240 | C41: =INDEX(Reference!$B$2:$B$39,MATCH($A41,Reference!$A$2:$A$39,0)) -> gram | D41: =$B41*INDEX(Reference!$C$2:$C$39,MATCH($A41,Reference!$A$2:$A$39,0)) -> 412.8 | E41: =$B41*INDEX(Reference!$D$2:$D$39,MATCH($A41,Reference!$A$2:$A$39,0)) -> 60 | F41: =$B41*INDEX(Reference!$E$2:$E$39,MATCH($A41,Reference!$A$2:$A$39,0)) -> 19.2 | G41: =$B41*INDEX(Reference!$F$2:$F$39,MATCH($A41,Reference!$A$2:$A$39,0)) -> 0 | H41: =$B41*INDEX(Reference!$G$2:$G$39,MATCH($A41,Reference!$A$2:$A$39,0)) -> 0
...
